//two parts of promise production and cosumption
//it used as async functionality
//resolve ka connection hai then ke saath


// const promise1 = new Promise(function (resolve, reject) {
//      setTimeout(() => {
//         console.log('async1 done')
//         resolve();
//      }, 1000);
// })
// promise1.then(function(){
//     console.log('promise1 resolved')
// })

// new Promise(function (resolve, reject) {
//     setTimeout(() => {
//        console.log('async2 done')
//        resolve();
//     }, 1000);
// }).then(() => {

//     console.log('promise2 resolved')
// });

// const promiseThree = new Promise(function(resolve, reject){
//     setTimeout(function(){
//         resolve({username: "Chai", email: "chai@example.com"})
//     }, 1000)
// })

// promiseThree.then(function(user){
//     console.log(user);
// })

// const promiseFour = new Promise(function(resolve, reject){
//     setTimeout(function(){
//         let error = false
//         if (!error) {
//             resolve({username: "hitesh", password: "123"})
//         } else {
//             reject('ERROR: Something went wrong')
//         }
//     }, 1000)
// })

//  promiseFour
//  .then((user) => {
//     console.log(user);
//     return user.username
// }).then((username) => {
//     console.log(username);
// }).catch(function(error){
//     console.log(error);
// }).finally(() => console.log("The promise is either resolved or rejected"))



// const promiseFive = new Promise(function(resolve, reject){
//     setTimeout(function(){
//         let error = false
//         if (!error) {
//             resolve({username: "javascript", password: "123"})
//         } else {
//             reject('ERROR: JS went wrong')
//         }
//     }, 1000)
// });

// async function consumePromiseFive(){
//     try {
//         const response = await promiseFive
//         console.log(response);
//     } catch (error) {
//         console.log(error);
//     }
// }

// consumePromiseFive()


// The fetch() function will reject the promise on some errors, but not if the server responds with an error status like 404: so we also check the response status and throw if it is not OK.
async function getAllUsers(){
    try {
        const response = await fetch('https://jsonplaceholder.typicode.com/users')

        const data = await response.json()
        console.log(data);
    } catch (error) {
        console.log("E: ", error);
    }
}

getAllUsers()

// fetch('https://api.github.com/users/hiteshchoudhary')
// .then((response) => {
//     return response.json()
// })
// .then((data) => {
//     console.log(data);
// })
// .catch((error) => console.log(error))

// promise.all
// yes this is also available, kuch reading aap b kro.